Workbook

Sheet MAR 2026
C10: DEPOSITOS | F10: SAQUES | I10: BALANÇO | J10: GERAL
A11: DATA | B11: Total (BRL) | C11: Deps Sum | D11: Number of Deposits | E11: Ticket | F11: W/D Sum | G11: Number of W/D | H11: Ticket | I11: NETCASH | J11: REGISTROS | K11: FTD | L11: UAP | M11: FTD AMOUNT. | N11: CASINO PAYOUT | O11: Sportsbook Turnover | P11: TURNOVER CASSINO | Q11: Casino GGR | R11: Total NGR | S11: Casino GGR %
A12: 46023 | B12: =C12*6.2 -> 29548.952 | C12: 4765.96 | D12: 366 | E12: =B12/$D$12 -> 80.734842 | F12: 3255.66 | G12: 80 | H12: =F12/G12 -> 40.69575 | I12: =C12-F12 -> 1510.3 | J12: 396 | K12: 116 | L12: 315 | N12: 43211.2 | O12: 852.25 | P12: 43245.69 | Q12: 34.49 | R12: -89.11 | S12: =R12/P12 -> -0.0020605522
A13: =A12+1 -> 46024 | B13: =C13*6.2 -> 20633.042 | C13: 3327.91 | D13: 323 | E13: =B13/$D$12 -> 56.374432 | F13: 2899.92 | G13: 66 | H13: =F13/G13 -> 43.938182 | I13: =C13-F13 -> 427.99 | J13: 409 | K13: 112 | L13: 308 | N13: 38629.47 | O13: 579.88 | P13: 38283.35 | Q13: -346.12 | R13: -210.15 | S13: =R13/P13 -> -0.0054893315
A14: =A13+1 -> 46025 | B14: =C14*6.2 -> 26181.05 | C14: 4222.75 | D14: 319 | E14: =B14/$D$12 -> 71.532923 | F14: 4750.3 | G14: 61 | H14: =F14/G14 -> 77.87377 | I14: =C14-F14 -> -527.55 | J14: 291 | K14: 102 | L14: 336 | N14: 47724.59 | O14: 500.73 | P14: 48474.54 | Q14: 749.95 | R14: 613.23 | S14: =R14/P14 -> 0.012650558
A15: =A14+1 -> 46026 | B15: =C15*6.2 -> 50149.32 | C15: 8088.6 | D15: 286 | E15: =B15/$D$12 -> 137.02 | F15: 3799.72 | G15: 61 | H15: =F15/G15 -> 62.290492 | I15: =C15-F15 -> 4288.88 | J15: 161 | K15: 63 | L15: 250 | N15: 55781.85 | O15: 364.63 | P15: 60416.35 | Q15: 4634.5 | R15: 4928.64 | S15: =R15/P15 -> 0.081577917
A16: =A15+1 -> 46027 | B16: =C16*6.2 -> 20125.51 | C16: 3246.05 | D16: 177 | E16: =B16/$D$12 -> 54.987732 | F16: 4932.73 | G16: 55 | H16: =F16/G16 -> 89.686 | I16: =C16-F16 -> -1686.68 | J16: 95 | K16: 16 | L16: 196 | N16: 43811.91 | O16: 1020.3 | P16: 40842.78 | Q16: -2969.13 | R16: -2857.22 | S16: =R16/P16 -> -0.06995655
A17: =A16+1 -> 46028 | B17: =C17*6.2 -> 41831.09 | C17: 6746.95 | D17: 248 | E17: =B17/$D$12 -> 114.2926 | F17: 4947.28 | G17: 57 | H17: =F17/G17 -> 86.794386 | I17: =C17-F17 -> 1799.67 | J17: 68 | K17: 15 | L17: 217 | N17: 54267.78 | O17: 583.65 | P17: 51324.33 | Q17: -2943.45 | R17: -2646.28 | S17: =R17/P17 -> -0.051559952
A18: =A17+1 -> 46029 | B18: =C18*6.2 -> 33563.08 | C18: 5413.4 | D18: 241 | E18: =B18/$D$12 -> 91.702404 | F18: 6579.12 | G18: 70 | H18: =F18/G18 -> 93.987429 | I18: =C18-F18 -> -1165.72 | J18: 68 | K18: 15 | L18: 187 | N18: 63619.04 | O18: 713.43 | P18: 64140.01 | Q18: 520.97 | R18: 72.22 | S18: =R18/P18 -> 0.0011259743
A19: =A18+1 -> 46030 | B19: =C19*6.2 -> 27896.714 | C19: 4499.47 | D19: 213 | E19: =B19/$D$12 -> 76.22053 | F19: 3349.1 | G19: 64 | H19: =F19/G19 -> 52.329687 | I19: =C19-F19 -> 1150.37 | J19: 177 | K19: 22 | L19: 195 | N19: 49359.44 | O19: 1228.12 | P19: 51221.92 | Q19: 1862.48 | R19: 2256.11 | S19: =R19/P19 -> 0.044045791
A20: =A19+1 -> 46031 | B20: =C20*6.2 -> 28969.562 | C20: 4672.51 | D20: 173 | E20: =B20/$D$12 -> 79.151809 | F20: 3568.21 | G20: 55 | H20: =F20/G20 -> 64.876545 | I20: =C20-F20 -> 1104.3 | J20: 58 | K20: 5 | L20: 164 | N20: 38079.49 | O20: 854.43 | P20: 40800.73 | Q20: 2721.24 | R20: 2456.29 | S20: =R20/P20 -> 0.060202109
A21: =A20+1 -> 46032 | B21: =C21*6.2 -> 37893.408 | C21: 6111.84 | D21: 225 | E21: =B21/$D$12 -> 103.5339 | F21: 5111.32 | G21: 64 | H21: =F21/G21 -> 79.864375 | I21: =C21-F21 -> 1000.52 | J21: 128 | K21: 58 | L21: 220 | N21: 43326.97 | O21: 1956.29 | P21: 47404.75 | Q21: 4077.78 | R21: 4190.64 | S21: =R21/P21 -> 0.088401268
A22: =A21+1 -> 46033 | B22: =C22*6.2 -> 27264.81 | C22: 4397.55 | D22: 233 | E22: =B22/$D$12 -> 74.494016 | F22: 4495.81 | G22: 56 | H22: =F22/G22 -> 80.282321 | I22: =C22-F22 -> -98.26 | J22: 168 | K22: 77 | L22: 275 | N22: 37086.39 | O22: 977.88 | P22: 36489.56 | Q22: -596.83 | R22: -369.38 | S22: =R22/P22 -> -0.010122895
A23: =A22+1 -> 46034 | B23: =C23*6.2 -> 39939.594 | C23: 6441.87 | D23: 225 | E23: =B23/$D$12 -> 109.12457 | F23: 4420.8 | G23: 56 | H23: =F23/G23 -> 78.942857 | I23: =C23-F23 -> 2021.07 | J23: 130 | K23: 49 | L23: 266 | N23: 54171.44 | O23: 526.24 | P23: 50675.13 | Q23: -3496.31 | R23: -3151.64 | S23: =R23/P23 -> -0.062193032
A24: =A23+1 -> 46035 | B24: =C24*6.2 -> 30704.632 | C24: 4952.36 | D24: 243 | E24: =B24/$D$12 -> 83.892437 | F24: 5598.09 | G24: 55 | H24: =F24/G24 -> 101.78345 | I24: =C24-F24 -> -645.73 | J24: 72 | K24: 31 | L24: 220 | N24: 59583.52 | O24: 803.16 | P24: 65311.15 | Q24: 5727.63 | R24: 5724.34 | S24: =R24/P24 -> 0.087647209
... A34: =A33+1 -> 46045 | B34: =C34*6.2 -> 76711.174 | C34: 12372.77 | D34: 555 | E34: =B34/$D$12 -> 209.59337 | F34: 11732.72 | G34: 87 | H34: =F34/G34 -> 134.85885 | I34: =C34-F34 -> 640.05 | J34: 792 | K34: 286 | L34: 459 | N34: 78921.53 | O34: 708.02 | P34: 82260.99 | Q34: 3339.46 | R34: 3353.23 | S34: =R34/P34 -> 0.040763307
A35: =A34+1 -> 46046 | E35: =B35/$D$12 -> 0 | H35: =F35/G35 -> #DIV/0! | I35: =C35-F35 -> 0 | S35: =R35/P35 -> #DIV/0!
A36: =A35+1 -> 46047 | B36: =C36*6.2 -> 0 | E36: =B36/$D$12 -> 0 | H36: =F36/G36 -> #DIV/0! | I36: =C36-F36 -> 0 | S36: =R36/P36 -> #DIV/0!
A37: =A36+1 -> 46048 | B37: =C37*6.2 -> 0 | E37: =B37/$D$12 -> 0 | H37: =F37/G37 -> #DIV/0! | I37: =C37-F37 -> 0 | S37: =R37/P37 -> #DIV/0!
A38: =A37+1 -> 46049 | B38: =C38*6.2 -> 0 | E38: =B38/$D$12 -> 0 | H38: =F38/G38 -> #DIV/0! | I38: =C38-F38 -> 0 | S38: =R38/P38 -> #DIV/0!
A39: =A38+1 -> 46050 | B39: =C39*6.2 -> 0 | E39: =B39/$D$12 -> 0 | H39: =F39/G39 -> #DIV/0! | I39: =C39-F39 -> 0 | S39: =R39/P39 -> #DIV/0!
A40: =A39+1 -> 46051 | B40: =C40*6.2 -> 0 | E40: =B40/$D$12 -> 0 | H40: =F40/G40 -> #DIV/0! | I40: =C40-F40 -> 0 | S40: =R40/P40 -> #DIV/0!
A41: =A40+1 -> 46052 | B41: =C41*6.2 -> 0 | E41: =B41/$D$12 -> 0 | H41: =F41/G41 -> #DIV/0! | I41: =C41-F41 -> 0 | S41: =R41/P41 -> #DIV/0!
A42: =A41+1 -> 46053 | B42: =C42*6.2 -> 0 | E42: =B42/$D$12 -> 0 | H42: =F42/G42 -> #DIV/0! | I42: =C42-F42 -> 0 | S42: =R42/P42 -> #DIV/0!
A43: TOTAL | B43: =sum(B12:B42) -> 879624.32 | C43: =sum(C12:C42) -> 141874.89 | D43: =sum(D12:D42) -> 6301 | E43: =B43/D43 -> 139.60075 | F43: =sum(F12:F42) -> 101640.94 | G43: =sum(G12:G42) -> 1447 | H43: =F43/G43 -> 70.242529 | I43: =sum(I12:I42) -> 40233.95 | J43: =sum(J12:J42) -> 5098 | K43: =sum(K12:K42) -> 1786 | L43: =sum(L12:L42) -> 5943 | M43: =SUM(M12:M42) -> 0 | N43: =SUM(N12:N42)*6.2 -> 7083352.8 | O43: =SUM(O12:O42)*6.2 -> 145008.58 | P43: =SUM(P12:P42)*6.2 -> 7304726.4 | Q43: =SUM(Q12:Q42)*6.2 -> 221373.67 | R43: =SUM(R12:R42)*6.2 -> 227786.95 | S43: =Q43/P43 -> 0.030305538
C44: DEPOSITOS | D44: QTD. DEP | E44: TICKET DEPOSITOS | F44: SAQUES | G44: QTD. SAQUE | H44: TICKET SAQUE | I44: NETCASH LIQUIDO | J44: CONVERSÃO FTD | M44: REDEP. | N44: INATIVOS | O44: CHURN | P44: LTV | Q44: TX. GETWAY | R44: PLAT. FEE 15% | S44: MEDIA %
I45: =I43-Q45 -> 23552.441 | J45: =K43/J43 -> 0.35033346 | N45: =J43-K43 -> 3312 | O45: =N45/J43 -> 0.64966654 | P45: =Q43/K43 -> 123.94942 | Q45: =(B43+F43)*0.017 -> 16681.509 | R45: 35000

Sheet WALLET
I1: CAIXA WALLET
A2: DESCRIÇÃO | B2: DATA | C2: $ | D2: R$ | E2: PTAX | F2: OBS SITUAÇÃO | G2: OBS SITUAÇÃO
A4: SAQUES DIGITO VIA CRIPTOATIVOS | B4: 45980 | C4: 371.0575 | G4: EFETUADO
A5: SAQUES DIGITO VIA CRIPTOATIVOS | B5: 45980 | C5: 9259.2593 | G5: EFETUADO | I5: CAIXA WALLET CRIPTO ATUALMENTE | J5: VALOR
A6: SAQUES DIGITO VIA CRIPTOATIVOS | B6: 45989 | C6: 4454.9426 | G6: EFETUADO | I6: USDT | J6: =SUM(C42:C48) -> 22679.385
A7: SAQUES DIGITO VIA CRIPTOATIVOS | B7: 45992 | C7: 9259.2593 | G7: EFETUADO | I7: LAST PTAX | J7: 5.39
A8: SAQUES WALLET | B8: 45992 | C8: -10012 | D8: =PAGAMENTOS!C20 -> -54075.6 | E8: =D8/C8 -> 5.4010787 | F8: Pagamento Fluxrise (reembolso trafego affbr) | G8: EFETUADO | I8: VALOR R$ | J8: =J6*J7 -> 122241.88
A9: SAQUES DIGITO VIA CRIPTOATIVOS | B9: 45999 | C9: 9157.5092 | G9: EFETUADO
A10: SAQUES DIGITO VIA CRIPTOATIVOS | B10: 46003 | C10: 4578.7546 | G10: EFETUADO
A11: SAQUES DIGITO VIA CRIPTOATIVOS | B11: 46008 | C11: 4504.5045 | G11: EFETUADO
A12: SAQUES WALLET | B12: =PAGAMENTOS!B24 -> 46011 | C12: -28000 | D12: =PAGAMENTOS!C24 -> -152320 | E12: =D12/C12 -> 5.44 | F12: Saques e distribuicao | G12: EFETUADO
A13: SAQUES DIGITO VIA CRIPTOATIVOS | B13: 46013 | C13: 7168.4588 | G13: EFETUADO
A14: SAQUES DIGITO VIA CRIPTOATIVOS | B14: 46014 | C14: 1773.0496 | G14: EFETUADO
A15: SAQUES DIGITO VIA CRIPTOATIVOS | B15: 46017 | C15: 5357.1429 | G15: EFETUADO
A16: SAQUES WALLET | B16: 46017 | C16: -5806.69 | F16: Fatura GGR | G16: EFETUADO
A17: SAQUES WALLET | B17: 46017 | C17: -12043 | D17: =C17*5.54 -> -66718.22 | E17: 5.54 | F17: Saques e distribuicao | G17: EFETUADO
A18: SAQUES DIGITO VIA CRIPTOATIVOS | B18: 46022 | C18: 5415.1625 | G18: EFETUADO
A19: SAQUES DIGITO VIA CRIPTOATIVOS | B19: 46029 | C19: 10110.294 | G19: EFETUADO
A20: SAQUES DIGITO VIA CRIPTOATIVOS | B20: 46030 | C20: 4587.156 | G20: EFETUADO
A21: SAQUES DIGITO VIA CRIPTOATIVOS | B21: 46036 | C21: 4595.5882 | G21: EFETUADO
A22: SAQUES WALLET | B22: 46036 | C22: =SUM(C18:C21)*-1 -> -24708.201 | E22: 5.39 | F22: Saques e distribuicao_Sheet Saque 14.01 | G22: EFETUADO
A23: SAQUES DIGITO VIA CRIPTOATIVOS | B23: 46038 | C23: 4604.0516 | G23: EFETUADO
A24: SAQUES DIGITO VIA CRIPTOATIVOS | B24: =B23+3 -> 46041 | C24: 7366.4825 | G24: EFETUADO
A25: SAQUES DIGITO VIA CRIPTOATIVOS | B25: =B24+3 -> 46044 | C25: 3731.3433 | G25: EFETUADO
A26: SAQUES DIGITO VIA CRIPTOATIVOS | B26: =B25+1 -> 46045 | C26: 4672.8972 | G26: EFETUADO
A27: SAQUES DIGITO VIA CRIPTOATIVOS | B27: =B26+3 -> 46048 | C27: 7476.6355 | G27: EFETUADO
A28: PAGAMENTO VIA UST DIRETA | B28: =B27 -> 46048 | C28: -1172 | D28: =E28*C28 -> -6797.6 | E28: 5.8 | F28: Pagamento Julia 7.020,00 BRL | G28: EFETUADO
A29: PAGAMENTO VIA UST DIRETA | B29: =B28 -> 46048 | C29: -10000 | D29: =E29*C29 -> -58000 | E29: 5.8 | F29: VALOR USADO AFFBR | G29: EFETUADO
A30: SAQUES DIGITO VIA CRIPTOATIVOS | B30: =B28+1 -> 46049 | C30: 3738.3178 | G30: EFETUADO
A31: PAGAMENTO VIA UST DIRETA | B31: =B30 -> 46049 | C31: -822 | D31: =E31*C31 -> -4767.6 | E31: 5.8 | F31: Setup + plano starter blacktrack | G31: EFETUADO
A32: SAQUES DIGITO VIA CRIPTOATIVOS | B32: =B31+2 -> 46051 | C32: 3787.8788 | G32: EFETUADO
A33: SAQUES DIGITO VIA CRIPTOATIVOS | B33: =B32+1 -> 46052 | C33: 4699.2481 | G33: EFETUADO
A34: PAGAMENTO VIA UST DIRETA | B34: 46053 | C34: -10518 | F34: Invoice em Euros para Phoenix | G34: EFETUADO
A35: SAQUES DIGITO VIA CRIPTOATIVOS | B35: 05/02/0226 | C35: 4690.4315 | G35: EFETUADO
A36: SAQUES DIGITO VIA CRIPTOATIVOS | B36: 46063 | C36: 1893.9394 | G36: EFETUADO
A37: SAQUES DIGITO VIA CRIPTOATIVOS | B37: =B36+1 -> 46064 | C37: 7935.9261 | G37: EFETUADO
A38: SAQUES DIGITO VIA CRIPTOATIVOS | B38: =B37+1 -> 46065 | C38: 1423.4405 | G38: EFETUADO
A39: SAQUES DIGITO VIA CRIPTOATIVOS | B39: =B38+4 -> 46069 | C39: 1192.1626 | G39: EFETUADO
A40: SAQUES DIGITO VIA CRIPTOATIVOS | B40: =B39+3 -> 46072 | C40: 4655.4935 | G40: EFETUADO
A41: SAQUES DIGITO VIA CRIPTOATIVOS | B41: =B40+4 -> 46076 | C41: 9433.9623 | G41: EFETUADO
...

Sheet FEV 2026
C10: DEPOSITOS | F10: SAQUES | I10: BALANÇO | J10: GERAL
A11: DATA | B11: Total (BRL) | C11: Deps Sum | D11: Number of Deposits | E11: Ticket | F11: W/D Sum | G11: Number of W/D | H11: Ticket | I11: NETCASH | J11: REGISTROS | K11: FTD | L11: UAP | M11: FTD AMOUNT. | N11: CASINO PAYOUT | O11: Sportsbook Turnover | P11: CASINO TURNOVER | Q11: Casino GGR | R11: Total NGR | S11: Casino GGR %
A12: 46054 | B12: =C12*6.2 -> 26576.052 | C12: 4286.46 | D12: 221 | E12: =B12/$D$12 -> 120.25363 | F12: 4717.05 | G12: 63 | H12: =F12/G12 -> 74.87381 | I12: =C12-F12 -> -430.59 | J12: 134 | K12: 45 | L12: 268 | N12: 47342.97 | O12: 893.33 | P12: 47823.9 | Q12: 480.93 | R12: 294.13 | S12: =R12/P12 -> 0.0061502721
A13: =A12+1 -> 46055 | B13: =C13*6.2 -> 33848.466 | C13: 5459.43 | D13: 265 | E13: =B13/$D$12 -> 153.16048 | F13: 3526.51 | G13: 65 | H13: =F13/G13 -> 54.254 | I13: =C13-F13 -> 1932.92 | J13: 104 | K13: 34 | L13: 227 | N13: 39515.92 | O13: 975.8 | P13: 41912.21 | Q13: 2396.29 | R13: 2511.83 | S13: =R13/P13 -> 0.059930746
A14: =A13+1 -> 46056 | B14: =C14*6.2 -> 29323.334 | C14: 4729.57 | D14: 301 | E14: =B14/$D$12 -> 132.68477 | F14: 3090.58 | G14: 74 | H14: =F14/G14 -> 41.764595 | I14: =C14-F14 -> 1638.99 | J14: 178 | K14: 41 | L14: 235 | N14: 45165.31 | O14: 682.99 | P14: 46257.71 | Q14: 1092.4 | R14: 1306.62 | S14: =R14/P14 -> 0.028246534
A15: =A14+1 -> 46057 | B15: =C15*6.2 -> 35744.426 | C15: 5765.23 | D15: 269 | E15: =B15/$D$12 -> 161.73948 | F15: 4745.47 | G15: 75 | H15: =F15/G15 -> 63.272933 | I15: =C15-F15 -> 1019.76 | J15: 147 | K15: 35 | L15: 210 | N15: 38256.55 | O15: 546.44 | P15: 38768.09 | Q15: 511.54 | R15: 378.42 | S15: =R15/P15 -> 0.0097611206
A16: =A15+1 -> 46058 | B16: =C16*6.2 -> 41932.398 | C16: 6763.29 | D16: 337 | E16: =B16/$D$12 -> 189.73936 | F16: 5967.93 | G16: 92 | H16: =F16/G16 -> 64.868804 | I16: =C16-F16 -> 795.36 | J16: 123 | K16: 40 | L16: 256 | N16: 53284.85 | O16: 1303.51 | P16: 50177.04 | Q16: -3107.81 | R16: -2312.69 | S16: =R16/P16 -> -0.046090602
A17: =A16+1 -> 46059 | B17: =C17*6.2 -> 40987.642 | C17: 6610.91 | D17: 264 | E17: =B17/$D$12 -> 185.46444 | F17: 6516.06 | G17: 99 | H17: =F17/G17 -> 65.818788 | I17: =C17-F17 -> 94.85 | J17: 95 | K17: 29 | L17: 256 | N17: 54524.97 | O17: 825.55 | P17: 56484.26 | Q17: 1959.29 | R17: 2363.7 | S17: =R17/P17 -> 0.041847056
A18: =A17+1 -> 46060 | B18: =C18*6.2 -> 32434.494 | C18: 5231.37 | D18: 280 | E18: =B18/$D$12 -> 146.76242 | F18: 3455.54 | G18: 93 | H18: =F18/G18 -> 37.156344 | I18: =C18-F18 -> 1775.83 | J18: 108 | K18: 43 | L18: 226 | N18: 63645.18 | O18: 256.22 | P18: 61845.77 | Q18: -1799.41 | R18: -1844.11 | S18: =R18/P18 -> -0.029817884
A19: =A18+1 -> 46061 | B19: =C19*6.2 -> 19035.302 | C19: 3070.21 | D19: 207 | E19: =B19/$D$12 -> 86.132588 | F19: 5208.74 | G19: 68 | H19: =F19/G19 -> 76.599118 | I19: =C19-F19 -> -2138.53 | J19: 148 | K19: 48 | L19: 188 | N19: 30990.32 | O19: 243.34 | P19: 30061.58 | Q19: -928.74 | R19: -1038.37 | S19: =R19/P19 -> -0.034541431
A20: =A19+1 -> 46062 | B20: =C20*6.2 -> 39440.122 | C20: 6361.31 | D20: 363 | E20: =B20/$D$12 -> 178.46209 | F20: 5412.76 | G20: 145 | H20: =F20/G20 -> 37.329379 | I20: =C20-F20 -> 948.55 | J20: 267 | K20: 92 | L20: 264 | N20: 62212.89 | O20: 268.08 | P20: 64822.43 | Q20: 2609.54 | R20: 2623.22 | S20: =R20/P20 -> 0.040467783
A21: =A20+1 -> 46063 | B21: =C21*6.2 -> 62923.614 | C21: 10148.97 | D21: 366 | E21: =B21/$D$12 -> 284.72224 | F21: 4293.33 | G21: 79 | H21: =F21/G21 -> 54.345949 | I21: =C21-F21 -> 5855.64 | J21: 317 | K21: 108 | L21: 308 | N21: 102052.3 | O21: 783.77 | P21: 109405.77 | Q21: 7353.47 | R21: 7774.25 | S21: =R21/P21 -> 0.071058866
A22: =A21+1 -> 46064 | B22: =C22*6.2 -> 51598.508 | C22: 8322.34 | D22: 343 | E22: =B22/$D$12 -> 233.47741 | F22: 3768.86 | G22: 68 | H22: =F22/G22 -> 55.424412 | I22: =C22-F22 -> 4553.48 | J22: 323 | K22: 107 | L22: 314 | N22: 62449.1 | O22: 779.06 | P22: 64617.9 | Q22: 2168.8 | R22: 1951.48 | S22: =R22/P22 -> 0.030200301
A23: =A22+1 -> 46065 | B23: =C23*6.2 -> 22340.584 | C23: 3603.32 | D23: 335 | E23: =B23/$D$12 -> 101.08862 | F23: 5655.99 | G23: 71 | H23: =F23/G23 -> 79.661831 | I23: =C23-F23 -> -2052.67 | J23: 234 | K23: 84 | L23: 327 | N23: 53599.39 | O23: 438.34 | P23: 55485.01 | Q23: 1885.62 | R23: 1977.8 | S23: =R23/P23 -> 0.035645664
A24: =A23+1 -> 46066 | B24: =C24*6.2 -> 30301.694 | C24: 4887.37 | D24: 366 | E24: =B24/$D$12 -> 137.11174 | F24: 5054.21 | G24: 62 | H24: =F24/G24 -> 81.519516 | I24: =C24-F24 -> -166.84 | J24: 325 | K24: 89 | L24: 338 | N24: 54992.96 | O24: 408.98 | P24: 57463.65 | Q24: 2470.69 | R24: 2326.35 | S24: =R24/P24 -> 0.040483854
... A39: =A38+1 -> 46081 | B39: =C39*6.2 -> 28714.742 | C39: 4631.41 | D39: 347 | E39: =B39/$D$12 -> 129.93096 | F39: 3076.73 | G39: 69 | H39: =F39/G39 -> 44.59029 | I39: =C39-F39 -> 1554.68 | J39: 334 | K39: 116 | L39: 324 | N39: 57207 | O39: 904.57 | P39: 60330.55 | Q39: 3123.55 | R39: 2905.43 | S39: =R39/P39 -> 0.04815852
A40: TOTAL | B40: =sum(B12:B39) -> 973022.11 | C40: =sum(C12:C39) -> 156939.05 | D40: =sum(D12:D39) -> 8756 | E40: =B40/D40 -> 111.12633 | F40: =937493-258258.65 -> 679234.35 | G40: =sum(G12:G39) -> 1881 | H40: =F40/G40 -> 361.10279 | I40: =B40-F40 -> 293787.76 | J40: =sum(J12:J39) -> 6550 | K40: =sum(K12:K39) -> 2298 | L40: =sum(L12:L39) -> 7809 | M40: =SUM(M12:M39) -> 0 | N40: =SUM(N12:N39)*6.2 -> 8732781.7 | O40: =SUM(O12:O39)*6.2 -> 96822.238 | P40: =SUM(P12:P39)*6.2 -> 9082871.7 | Q40: =SUM(Q12:Q39)*6.2 -> 350089.94 | R40: =SUM(R12:R39)*6.2 -> 362707.25 | S40: =Q40/P40 -> 0.038543971
C41: DEPOSITOS | D41: QTD. DEP | E41: TICKET DEPOSITOS | F41: SAQUES | G41: QTD. SAQUE | H41: TICKET SAQUE | I41: NETCASH LIQUIDO | J41: CONVERSÃO FTD | M41: REDEP. | N41: INATIVOS | O41: CHURN | P41: LTV | Q41: TX. GETWAY | R41: PLAT. FEE 15% | S41: MEDIA %
I42: =I40-Q42 -> 279154.73 | J42: =K40/J40 -> 0.35083969 | N42: =J40-K40 -> 4252 | O42: =N42/J40 -> 0.64916031 | P42: =Q40/K40 -> 152.34549 | Q42: =(C40+F40)*0.0175 -> 14633.034 | R42: =Q40*0.15 -> 52513.492

Sheet JAN 2026
C10: DEPOSITOS | F10: SAQUES | I10: BALANÇO | J10: GERAL
A11: DATA | B11: Total (BRL) | C11: Deps Sum | D11: Number of Deposits | E11: Ticket | F11: W/D Sum | G11: Number of W/D | H11: Ticket | I11: NETCASH | J11: REGISTROS | K11: FTD | L11: UAP | M11: FTD AMOUNT. | N11: CASINO PAYOUT | O11: Sportsbook Turnover | P11: TURNOVER CASSINO | Q11: Casino GGR | R11: comparativo | S11: Total NGR | T11: Casino GGR %
A12: 46023 | B12: =C12*6.2 -> 31989.396 | C12: 5159.58 | D12: 314 | E12: =B12/$D$12 -> 101.87706 | F12: 4440.07 | G12: 186 | H12: =F12/G12 -> 23.871344 | I12: =C12-F12 -> 719.51 | J12: 169 | K12: 146 | L12: 264 | N12: 33031.4 | O12: 0 | P12: 28251.67 | Q12: -4779.73 | R12: -4779.73 | S12: -4779.73 | T12: -16.92
A13: =A12+1 -> 46024 | B13: =C13*6.2 -> 36552.906 | C13: 5895.63 | D13: 285 | E13: =B13/$D$12 -> 116.41053 | F13: 8231.05 | G13: 142 | H13: =F13/G13 -> 57.965141 | I13: =C13-F13 -> -2335.42 | J13: 98 | K13: 67 | L13: 221 | N13: 43702.4 | O13: 0 | P13: 42664.33 | Q13: -1038.07 | R13: -1038.07 | S13: -1038.07 | T13: -2.43
A14: =A13+1 -> 46025 | B14: =C14*6.2 -> 29237.34 | C14: 4715.7 | D14: 215 | E14: =B14/$D$12 -> 93.112548 | F14: 3740.79 | G14: 84 | H14: =F14/G14 -> 44.533214 | I14: =C14-F14 -> 974.91 | J14: 45 | K14: 21 | L14: 151 | N14: 69435.32 | O14: 0 | P14: 88139.28 | Q14: 18703.96 | R14: 18703.96 | S14: 18703.96 | T14: 21.22
A15: =A14+1 -> 46026 | B15: =C15*6.2 -> 25910.606 | C15: 4179.13 | D15: 207 | E15: =B15/$D$12 -> 82.517854 | F15: 3253.16 | G15: 60 | H15: =F15/G15 -> 54.219333 | I15: =C15-F15 -> 925.97 | J15: 44 | K15: 20 | L15: 155 | N15: 27115.72 | O15: 4.64 | P15: 29494.14 | Q15: 2381.42 | R15: 2381.42 | S15: 2381.42 | T15: 8.06
A16: =A15+1 -> 46027 | B16: =C16*6.2 -> 28393.21 | C16: 4579.55 | D16: 213 | E16: =B16/$D$12 -> 90.424236 | F16: 2183.49 | G16: 63 | H16: =F16/G16 -> 34.658571 | I16: =C16-F16 -> 2396.06 | J16: 111 | K16: 18 | L16: 155 | N16: 26098.77 | O16: 34.97 | P16: 27151.21 | Q16: 1041.43 | R16: 1041.43 | S16: 1041.43 | T16: 3.88
A17: =A16+1 -> 46028 | B17: =C17*6.2 -> 85272.692 | C17: 13753.66 | D17: 259 | E17: =B17/$D$12 -> 271.56908 | F17: 6315.92 | G17: 95 | H17: =F17/G17 -> 66.483368 | I17: =C17-F17 -> 7437.74 | J17: 112 | K17: 21 | L17: 170 | N17: 137606.99 | O17: 50.32 | P17: 140995.74 | Q17: 3401.67 | R17: 3401.67 | S17: 3401.67 | T17: 2.4
A18: =A17+1 -> 46029 | B18: =C18*6.2 -> 38023.36 | C18: 6132.8 | D18: 240 | E18: =B18/$D$12 -> 121.0935 | F18: 4349.96 | G18: 98 | H18: =F18/G18 -> 44.387347 | I18: =C18-F18 -> 1782.84 | J18: 88 | K18: 23 | L18: 179 | N18: 54503.98 | O18: 24.36 | P18: 61606.9 | Q18: 7082.21 | R18: 7082.21 | S18: 7082.21 | T18: 11.53
A19: =A18+1 -> 46030 | B19: =C19*6.2 -> 51031.146 | C19: 8230.83 | D19: 263 | E19: =B19/$D$12 -> 162.51957 | F19: 4576.62 | G19: 94 | H19: =F19/G19 -> 48.687447 | I19: =C19-F19 -> 3654.21 | J19: 54 | K19: 27 | L19: 228 | N19: 47683.17 | O19: 5.25 | P19: 52063.86 | Q19: 4385.94 | R19: 4385.94 | S19: 4385.94 | T19: 8.41
A20: =A19+1 -> 46031 | B20: =C20*6.2 -> 38627.054 | C20: 6230.17 | D20: 343 | E20: =B20/$D$12 -> 123.0161 | F20: 4494.78 | G20: 133 | H20: =F20/G20 -> 33.795338 | I20: =C20-F20 -> 1735.39 | J20: 229 | K20: 76 | L20: 272 | N20: 35571.63 | O20: 3.33 | P20: 36714.61 | Q20: 1146.49 | R20: 1146.49 | S20: 1146.49 | T20: 3.11
A21: =A20+1 -> 46032 | B21: =C21*6.2 -> 36583.038 | C21: 5900.49 | D21: 362 | E21: =B21/$D$12 -> 116.50649 | F21: 6580.79 | G21: 125 | H21: =F21/G21 -> 52.64632 | I21: =C21-F21 -> -680.3 | J21: 137 | K21: 56 | L21: 248 | N21: 42414.3 | O21: 6.21 | P21: 43409.29 | Q21: 960.66 | R21: 960.66 | S21: 960.66 | T21: 2.29
A22: =A21+1 -> 46033 | B22: =C22*6.2 -> 29779.84 | C22: 4803.2 | D22: 255 | E22: =B22/$D$12 -> 94.840255 | F22: 3453.06 | G22: 77 | H22: =F22/G22 -> 44.844935 | I22: =C22-F22 -> 1350.14 | J22: 85 | K22: 15 | L22: 180 | N22: 30378.54 | O22: 31.93 | P22: 32421.86 | Q22: 2054.59 | R22: 2054.59 | S22: 2054.59 | T22: 6.3
A23: =A22+1 -> 46034 | B23: =C23*6.2 -> 31115.63 | C23: 5018.65 | D23: 264 | E23: =B23/$D$12 -> 99.094363 | F23: 4559.21 | G23: 66 | H23: =F23/G23 -> 69.078939 | I23: =C23-F23 -> 459.44 | J23: 96 | K23: 13 | L23: 184 | N23: 37369.71 | O23: 79.97 | P23: 39379 | Q23: 2084.35 | R23: 2084.35 | S23: 2084.35 | T23: 5.1
A24: =A23+1 -> 46035 | B24: =C24*6.2 -> 34605.486 | C24: 5581.53 | D24: 299 | E24: =B24/$D$12 -> 110.20855 | F24: 5464.85 | G24: 136 | H24: =F24/G24 -> 40.182721 | I24: =C24-F24 -> 116.68 | J24: 201 | K24: 91 | L24: 268 | N24: 40219.28 | O24: 30.25 | P24: 41602.15 | Q24: 1408.32 | R24: 1408.32 | S24: 1408.32 | T24: 3.32
... A42: =A41+1 -> 46053 | B42: =C42*6.2 -> 24090.658 | C42: 3885.59 | D42: 309 | E42: =B42/$D$12 -> 76.721841 | F42: 4392.34 | G42: 63 | H42: =F42/G42 -> 69.719683 | I42: =C42-F42 -> -506.75 | J42: 171 | K42: 57 | L42: 259 | N42: 107805.27 | O42: 476.68 | P42: 73716.51 | Q42: -34054.07 | R42: -34054.07 | S42: -34054.07 | T42: 2.8
A43: TOTAL | B43: 1268028 | C43: =sum(C12:C42) -> 208887.42 | D43: =sum(D12:D42) -> 9691 | E43: =B43/D43 -> 130.84594 | F43: 945498 | G43: =sum(G12:G42) -> 3233 | H43: =F43/G43 -> 292.45221 | I43: =B43-F43 -> 322530 | J43: =sum(J12:J42) -> 6070 | K43: =sum(K12:K42) -> 1701 | L43: =sum(L12:L42) -> 7459 | M43: =SUM(M12:M42) -> 0 | N43: =SUM(N12:N42)*6.2 -> 10287345 | O43: =SUM(O12:O42)*6.2 -> 125425.19 | P43: =SUM(P12:P42)*6.2 -> 17156473 | Q43: =SUM(Q12:Q42)*6.2 -> 6910338 | R43: =sum(R11:R42)*6.2 -> 446776.59 | S43: =SUM(S12:S42)*6.2 -> 6910338 | T43: =Q43/P43 -> 0.40278314
C44: DEPOSITOS | D44: QTD. DEP | E44: TICKET DEPOSITOS | F44: SAQUES | G44: QTD. SAQUE | H44: TICKET SAQUE | I44: NETCASH LIQUIDO | J44: CONVERSÃO FTD | M44: REDEP. | N44: INATIVOS | O44: CHURN | P44: LTV | Q44: TX. GETWAY | S44: PLAT. FEE 15% | T44: MEDIA %
I45: =I43-Q45 -> 284900.06 | J45: =K43/J43 -> 0.28023064 | N45: =J43-K43 -> 4369 | O45: =N45/J43 -> 0.71976936 | P45: =Q43/K43 -> 4062.515 | Q45: =(B43+F43)*0.017 -> 37629.942 | S45: 35000

Sheet DEZ 2025
C10: DEPOSITOS | F10: SAQUES | I10: BALANÇO | J10: GERAL
A11: DATA | B11: Total (BRL) | C11: Total (EURO) | D11: QTD | E11: Ticket | F11: Total (EURO) | G11: QTD | H11: Ticket | I11: NETCASH | J11: REGISTROS | K11: FTD | L11: UAP | M11: FTD AMOUNT. | N11: WINS | O11: TURNOVER SPTBS | P11: TURNOVER CASSINO | Q11: GGR | R11: NGR | S11: GGR%
A12: 45992 | B12: =C12*6 -> 40756.14 | C12: 6792.69 | D12: 317 | E12: =C12/D12 -> 21.428044 | F12: 5529.34 | G12: 86 | H12: =F12/G12 -> 64.294651 | I12: =C12-F12 -> 1263.35 | J12: 107 | K12: 47 | L12: 226 | N12: 53201.24 | P12: 48164.98 | Q12: -5036.26 | R12: -5083.49 | S12: -10.46
A13: =A12+1 -> 45993 | B13: =C13*6 -> 43916.4 | C13: 7319.4 | D13: 279 | E13: =C13/D13 -> 26.234409 | F13: 8897.53 | G13: 100 | H13: =F13/G13 -> 88.9753 | I13: =C13-F13 -> -1578.13 | J13: 98 | K13: 52 | L13: 240 | N13: 62513.87 | P13: 63163.32 | Q13: 649.45 | R13: 745.28 | S13: 1.03
A14: =A13+1 -> 45994 | B14: =C14*6 -> 47063.76 | C14: 7843.96 | D14: 294 | E14: =C14/D14 -> 26.680136 | F14: 4720.75 | G14: 89 | H14: =F14/G14 -> 53.042135 | I14: =C14-F14 -> 3123.21 | J14: 103 | K14: 41 | L14: 235 | N14: 57513.65 | P14: 64089.54 | Q14: 6575.89 | R14: 6334.3 | S14: 10.26
A15: =A14+1 -> 45995 | B15: =C15*6 -> 31916.58 | C15: 5319.43 | D15: 238 | E15: =C15/D15 -> 22.350546 | F15: 5622.08 | G15: 101 | H15: =F15/G15 -> 55.664158 | I15: =C15-F15 -> -302.65 | J15: 85 | K15: 31 | L15: 196 | N15: 34562.38 | P15: 34413.03 | Q15: -149.35 | R15: -72.12 | S15: -0.43
A16: =A15+1 -> 45996 | B16: =C16*6 -> 37990.14 | C16: 6331.69 | D16: 287 | E16: =C16/D16 -> 22.061638 | F16: 4496.57 | G16: 82 | H16: =F16/G16 -> 54.83622 | I16: =C16-F16 -> 1835.12 | J16: 92 | K16: 46 | L16: 247 | N16: 39278 | P16: 45879.09 | Q16: 6601.09 | R16: 6908.98 | S16: 14.39
A17: =A16+1 -> 45997 | B17: =C17*6 -> 51438.54 | C17: 8573.09 | D17: 395 | E17: =C17/D17 -> 21.704025 | F17: 5844.07 | G17: 117 | H17: =F17/G17 -> 49.949316 | I17: =C17-F17 -> 2729.02 | J17: 84 | K17: 41 | L17: 269 | N17: 71313.79 | P17: 75896.56 | Q17: 4582.77 | R17: 4590.37 | S17: 6.04
A18: =A17+1 -> 45998 | B18: =C18*6 -> 43127.76 | C18: 7187.96 | D18: 328 | E18: =C18/D18 -> 21.914512 | F18: 4621.32 | G18: 116 | H18: =F18/G18 -> 39.838966 | I18: =C18-F18 -> 2566.64 | J18: 97 | K18: 40 | L18: 228 | N18: 60198.97 | P18: 63673.17 | Q18: 3474.2 | R18: 3540.79 | S18: 5.46
A19: =A18+1 -> 45999 | B19: =C19*6 -> 41197.92 | C19: 6866.32 | D19: 318 | E19: =C19/D19 -> 21.592201 | F19: 4920.58 | G19: 114 | H19: =F19/G19 -> 43.162982 | I19: =C19-F19 -> 1945.74 | J19: 84 | K19: 28 | L19: 204 | N19: 61172.31 | P19: 65848.11 | Q19: 4675.8 | R19: 4676.05 | S19: 7.1
A20: =A19+1 -> 46000 | B20: =C20*6 -> 43665 | C20: 7277.5 | D20: 327 | E20: =C20/D20 -> 22.255352 | F20: 5750.19 | G20: 118 | H20: =F20/G20 -> 48.730424 | I20: =C20-F20 -> 1527.31 | J20: 107 | K20: 33 | L20: 205 | N20: 51721.14 | P20: 53084.72 | Q20: 1363.58 | R20: 1372.06 | S20: 2.57
A21: =A20+1 -> 46001 | B21: =C21*6 -> 65058.48 | C21: 10843.08 | D21: 613 | E21: =C21/D21 -> 17.688548 | F21: 9061.2 | G21: 354 | H21: =F21/G21 -> 25.59661 | I21: =C21-F21 -> 1781.88 | J21: 327 | K21: 270 | L21: 449 | N21: 67250.11 | P21: 68784.34 | Q21: 1534.23 | R21: 1532.1 | S21: 2.23
A22: =A21+1 -> 46002 | B22: =C22*6 -> 32403 | C22: 5400.5 | D22: 342 | E22: =C22/D22 -> 15.790936 | F22: 4079.44 | G22: 150 | H22: =F22/G22 -> 27.196267 | I22: =C22-F22 -> 1321.06 | J22: 117 | K22: 89 | L22: 229 | N22: 61966.63 | P22: 63009.14 | Q22: 1042.51 | R22: 1068.93 | S22: 1.65
A23: =A22+1 -> 46003 | B23: =C23*6 -> 33351.18 | C23: 5558.53 | D23: 276 | E23: =C23/D23 -> 20.139601 | F23: 5064.8 | G23: 82 | H23: =F23/G23 -> 61.765854 | I23: =C23-F23 -> 493.73 | J23: 87 | K23: 33 | L23: 197 | N23: 50746.21 | P23: 50865.7 | Q23: 119.49 | R23: 32.93 | S23: 0.23
A24: =A23+1 -> 46004 | B24: =C24*6 -> 32402.28 | C24: 5400.38 | D24: 265 | E24: =C24/D24 -> 20.378792 | F24: 2529 | G24: 74 | H24: =F24/G24 -> 34.175676 | I24: =C24-F24 -> 2871.38 | J24: 101 | K24: 33 | L24: 169 | N24: 31041.14 | P24: 32563.86 | Q24: 1522.72 | R24: 1530.62 | S24: 4.68
... A42: =A41+1 -> 46022 | B42: =C42*6 -> 24330.6 | C42: 4055.1 | D42: 367 | E42: =C42/D42 -> 11.049319 | F42: 3432.25 | G42: 227 | H42: =F42/G42 -> 15.120044 | I42: =C42-F42 -> 622.85 | J42: 217 | K42: 180 | L42: 325 | N42: 34295.9 | P42: 36517.05 | Q42: 2221.15 | R42: 2221.15 | S42: 6.08
A43: TOTAL | B43: =sum(B12:B42) -> 1177954.7 | C43: =sum(C12:C42) -> 196325.78 | D43: =sum(D12:D42) -> 10781 | E43: =B43/D43 -> 109.2621 | F43: =sum(F12:F42)*6 -> 931567.5 | G43: =sum(G12:G42) -> 3989 | H43: =F43/G43 -> 233.53409 | I43: =B43-F43 -> 246387.18 | J43: =sum(J12:J42) -> 4772 | K43: =sum(K12:K42) -> 2312 | L43: =sum(L12:L42) -> 7430 | M43: =SUM(M12:M42) -> 0 | N43: =SUM(N12:N42)*6 -> 9382561.6 | O43: =SUM(O12:O42) -> 0 | P43: =SUM(P12:P42)*6 -> 9639402.8 | Q43: =SUM(Q12:Q42)*6 -> 256841.22 | R43: =SUM(R12:R42)*6 -> 260123.94 | S43: =Q43/P43 -> 0.026644931
C44: DEPOSITOS | D44: QTD. DEP | E44: TICKET DEPOSITOS | F44: SAQUES | G44: QTD. SAQUE | H44: TICKET SAQUE | I44: NETCASH LIQUIDO | J44: CONVERSÃO FTD | M44: REDEP. | N44: INATIVOS | O44: CHURN | P44: LTV | Q44: TX. GETWAY | R44: PLAT. FEE 15% | S44: MEDIA %
I45: =I43-Q45 -> 226649.05 | J45: =K43/J43 -> 0.48449288 | N45: =J43-K43 -> 2460 | O45: =N45/J43 -> 0.51550712 | P45: =Q43/K43 -> 111.09049 | Q45: =(C43+F43)*0.0175 -> 19738.132 | R45: =Q43*0.15 -> 38526.183

Sheet NOV 2025
B10: DEPOSITOS | E10: SAQUES | H10: BALANÇO | I10: GERAL
A11: DATA | B11: Total | C11: QTD | D11: Ticket | E11: Total | F11: QTD | G11: Ticket | H11: NETCASH | I11: REGISTROS | J11: FTD | K11: UAP | L11: FTD AMOUNT. | M11: WINS | N11: TURNOVER SPTBS | O11: TURNOVER CASSINO | P11: GGR | Q11: NGR | R11: GGR%
A12: 45962 | B12: 0 | C12: 0 | D12: 0 | E12: 0 | F12: 0 | G12: 0 | H12: =B12-E12 -> 0 | I12: 0 | J12: 0 | K12: 0 | M12: 0 | N12: 0 | O12: 0 | P12: 0 | Q12: 0 | R12: 0
A13: 45963 | B13: 0 | C13: 0 | D13: 0 | E13: 0 | F13: 0 | G13: 0 | H13: =B13-E13 -> 0 | I13: 0 | J13: 0 | K13: 0 | M13: 0 | N13: 0 | O13: 0 | P13: 0 | Q13: 0 | R13: 0
A14: 45964 | B14: 0 | C14: 0 | D14: 0 | E14: 0 | F14: 0 | G14: 0 | H14: =B14-E14 -> 0 | I14: 0 | J14: 0 | K14: 0 | M14: 0 | N14: 0 | O14: 0 | P14: 0 | Q14: 0 | R14: 0
A15: 45965 | B15: 0 | C15: 0 | D15: 0 | E15: 0 | F15: 0 | G15: 0 | H15: =B15-E15 -> 0 | I15: 0 | J15: 0 | K15: 0 | M15: 0 | N15: 0 | O15: 0 | P15: 0 | Q15: 0 | R15: 0
A16: 45966 | B16: 0 | C16: 0 | D16: 0 | E16: 0 | F16: 0 | G16: 0 | H16: =B16-E16 -> 0 | I16: 0 | J16: 0 | K16: 0 | M16: 0 | N16: 0 | O16: 0 | P16: 0 | Q16: 0 | R16: 0
A17: 45967 | B17: 0 | C17: 0 | D17: 0 | E17: 0 | F17: 0 | G17: 0 | H17: =B17-E17 -> 0 | I17: 3 | J17: 0 | K17: 0 | M17: 0 | N17: 0 | O17: 0 | P17: 0 | Q17: 0 | R17: 0
A18: 45968 | B18: 0 | C18: 0 | D18: 0 | E18: 0 | F18: 0 | G18: 0 | H18: =B18-E18 -> 0 | I18: 0 | J18: 0 | K18: 0 | M18: 0 | N18: 0 | O18: 0 | P18: 0 | Q18: 0 | R18: 0
A19: 45969 | B19: 0 | C19: 0 | D19: 0 | E19: 0 | F19: 0 | G19: 0 | H19: =B19-E19 -> 0 | I19: 0 | J19: 0 | K19: 0 | M19: 0 | N19: 0 | O19: 0 | P19: 0 | Q19: 0 | R19: 0
A20: 45970 | B20: 0 | C20: 0 | D20: 0 | E20: 0 | F20: 0 | G20: 0 | H20: =B20-E20 -> 0 | I20: 0 | J20: 0 | K20: 0 | M20: 0 | N20: 0 | O20: 0 | P20: 0 | Q20: 0 | R20: 0
A21: 45971 | B21: 1.62 | C21: 1 | D21: =B21/C21 -> 1.62 | E21: 0 | F21: 0 | G21: 0 | H21: =B21-E21 -> 1.62 | I21: 2 | J21: 1 | K21: 1 | M21: 0.27 | N21: 0 | O21: 1.45 | P21: 1.18 | Q21: 1.18 | R21: =P21/O21 -> 0.8137931
A22: 45972 | B22: 8.08 | C22: 1 | D22: =B22/C22 -> 8.08 | E22: 0 | F22: 0 | G22: 0 | H22: =B22-E22 -> 8.08 | I22: 1 | J22: 1 | K22: 2 | M22: 2.52 | N22: 0 | O22: 5.74 | P22: 3.22 | Q22: 3.22 | R22: =P22/O22 -> 0.56097561
A23: 45973 | B23: 8.16 | C23: 1 | D23: =B23/C23 -> 8.16 | E23: 8.16 | F23: 1 | G23: =E23/F23 -> 8.16 | H23: =B23-E23 -> 0 | I23: 0 | J23: 1 | K23: 1 | M23: 0 | N23: 0 | O23: 0 | P23: 0 | Q23: 0 | R23: 0
A24: 45974 | B24: 757.39 | C24: 24 | D24: =B24/C24 -> 31.557917 | E24: 84.09 | F24: 6 | G24: =E24/F24 -> 14.015 | H24: =B24-E24 -> 673.3 | I24: 63 | J24: 21 | K24: 24 | M24: 662.64 | N24: 0.32 | O24: 836.12 | P24: 173.41 | Q24: 173.41 | R24: =P24/O24 -> 0.20739846
A25: 45975 | B25: 2329 | C25: 132 | D25: =B25/C25 -> 17.643939 | E25: 1160.98 | F25: 34 | G25: =E25/F25 -> 34.146471 | H25: =B25-E25 -> 1168.02 | I25: 149 | J25: 89 | K25: 107 | M25: 12741.91 | N25: 0 | O25: 13494.74 | P25: 752.83 | Q25: 752.83 | R25: =P25/O25 -> 0.055786921
A26: 45976 | B26: 3422.51 | C26: 135 | D26: =B26/C26 -> 25.351926 | E26: 1507.79 | F26: 54 | G26: =E26/F26 -> 27.922037 | H26: =B26-E26 -> 1914.72 | I26: 198 | J26: 61 | K26: 119 | M26: 24479.78 | N26: 0.33 | O26: 25028.3 | P26: 548.85 | Q26: 548.85 | R26: =P26/O26 -> 0.021929176
A27: 45977 | B27: 2143.37 | C27: 121 | D27: =B27/C27 -> 17.713802 | E27: 2339.73 | F27: 61 | G27: =E27/F27 -> 38.35623 | H27: =B27-E27 -> -196.36 | I27: 213 | J27: 41 | K27: 97 | M27: 25368.96 | N27: 0.33 | O27: 25014.45 | P27: -354.18 | Q27: -354.18 | R27: =P27/O27 -> -0.014159016
A28: 45978 | B28: 4068.43 | C28: 135 | D28: =B28/C28 -> 30.136519 | E28: 981.97 | F28: 30 | G28: =E28/F28 -> 32.732333 | H28: =B28-E28 -> 3086.46 | I28: 594 | J28: 45 | K28: 109 | M28: 27429.48 | N28: 0 | O28: 30109.94 | P28: 2680.46 | Q28: 2680.46 | R28: =P28/O28 -> 0.089022429
A29: 45979 | B29: 2695.35 | C29: 142 | D29: =B29/C29 -> 18.981338 | E29: 1714.28 | F29: 29 | G29: =E29/F29 -> 59.113103 | H29: =B29-E29 -> 981.07 | I29: 1834 | J29: 51 | K29: 124 | M29: 24154.73 | N29: 0 | O29: 19441.5 | P29: -4713.23 | Q29: -4713.23 | R29: =P29/O29 -> -0.2424314
A30: 45980 | B30: 12279.56 | C30: 275 | D30: =B30/C30 -> 44.652945 | E30: 5688.93 | F30: 79 | G30: =E30/F30 -> 72.011772 | H30: =B30-E30 -> 6590.63 | I30: 170 | J30: 119 | K30: 202 | M30: 142239.07 | N30: 8.49 | O30: 134164.65 | P30: -8065.93 | Q30: -8065.93 | R30: =P30/O30 -> -0.060119637
A31: 45981 | B31: 5538.09 | C31: 297 | D31: =B31/C31 -> 18.646768 | E31: 5301.62 | F31: 74 | G31: =E31/F31 -> 71.643514 | H31: =B31-E31 -> 236.47 | I31: 246 | J31: 106 | K31: 238 | M31: 41833.7 | N31: 30.15 | O31: 43983.77 | P31: 2173.01 | Q31: 2173.01 | R31: =P31/O31 -> 0.049404815
A32: 45982 | B32: 7116.61 | C32: 280 | D32: =B32/C32 -> 25.416464 | E32: 3770.01 | F32: 63 | G32: =E32/F32 -> 59.841429 | H32: =B32-E32 -> 3346.6 | I32: 165 | J32: 86 | K32: 250 | M32: 103868.96 | N32: 193.69 | O32: 103498.33 | P32: -441.96 | Q32: -441.96 | R32: =P32/O32 -> -0.0042702138
A33: 45983 | B33: 6364.03 | C33: 272 | D33: =B33/C33 -> 23.397169 | E33: 7828.72 | F33: 95 | G33: =E33/F33 -> 82.407579 | H33: =B33-E33 -> -1464.69 | I33: 153 | J33: 72 | K33: 219 | M33: 53234.61 | N33: 85.21 | O33: 51964.26 | P33: -1303.91 | Q33: -1303.91 | R33: =P33/O33 -> -0.025092439
A34: 45984 | B34: 6019.5 | C34: 280 | D34: =B34/C34 -> 21.498214 | E34: 4421.31 | F34: 75 | G34: =E34/F34 -> 58.9508 | H34: =B34-E34 -> 1598.19 | I34: 164 | J34: 74 | K34: 218 | M34: 50556.74 | N34: 39.46 | O34: 52435.27 | P34: 1915.49 | Q34: 1915.49 | R34: =P34/O34 -> 0.036530564
A35: 45985 | B35: 5127.05 | C35: 238 | D35: =B35/C35 -> 21.542227 | E35: 3960.47 | F35: 72 | G35: =E35/F35 -> 55.006528 | H35: =B35-E35 -> 1166.58 | I35: 110 | J35: 58 | K35: 193 | M35: 67579.47 | N35: 35.39 | O35: 77457.58 | P35: 9902.36 | Q35: 9902.36 | R35: =P35/O35 -> 0.12784236
A36: 45986 | B36: 3615.65 | C36: 228 | D36: =B36/C36 -> 15.858114 | E36: 3369.64 | F36: 76 | G36: 0 | H36: =B36-E36 -> 246.01 | I36: 101 | J36: 46 | K36: 189 | M36: 39380.5 | N36: 43.01 | O36: 37689.22 | P36: -1661.22 | Q36: -1661.22 | R36: =P36/O36 -> -0.044076794
A37: 45987 | B37: 6152.03 | C37: 260 | D37: =B37/C37 -> 23.661654 | E37: 6258.37 | F37: 82 | G37: =E37/F37 -> 76.321585 | H37: =B37-E37 -> -106.34 | I37: 150 | J37: 66 | K37: 227 | M37: 68537.56 | N37: 237.57 | O37: 75941.24 | P37: 7392.28 | Q37: 7392.28 | R37: =P37/O37 -> 0.097342103
A38: 45988 | B38: 7434.24 | C38: 274 | D38: =B38/C38 -> 27.132263 | E38: 5677.77 | F38: 87 | G38: =E38/F38 -> 65.261724 | H38: =B38-E38 -> 1756.47 | I38: 114 | J38: 49 | K38: 221 | M38: 84041.73 | N38: 117.55 | O38: 83405.64 | P38: -677.83 | Q38: -677.83 | R38: =P38/O38 -> -0.0081269084
A39: 45989 | B39: 7383.33 | C39: 286 | D39: =B39/C39 -> 25.815839 | E39: 4875.26 | F39: 84 | G39: =E39/F39 -> 58.03881 | H39: =B39-E39 -> 2508.07 | I39: 120 | J39: 56 | K39: 210 | M39: 62695.32 | N39: 21.13 | O39: 67587.68 | P39: 4913.2 | Q39: 4913.2 | R39: =P39/O39 -> 0.072693722
A40: 45990 | B40: 6801.93 | C40: 358 | D40: =B40/C40 -> 18.999804 | E40: 5554.01 | F40: 108 | G40: =E40/F40 -> 51.426019 | H40: =B40-E40 -> 1247.92 | I40: 122 | J40: 60 | K40: 252 | M40: 43800.44 | N40: 181.25 | O40: 44385.37 | P40: 664.74 | Q40: 664.74 | R40: =P40/O40 -> 0.014976556
A41: 45991 | B41: 5848.8 | C41: 275 | D41: =B41/C41 -> 21.268364 | E41: 3281.94 | F41: 68 | G41: =E41/F41 -> 48.263824 | H41: =B41-E41 -> 2566.86 | I41: 96 | J41: 45 | K41: 187 | M41: 39022.52 | N41: 46.78 | O41: 41583.82 | P41: 2565.52 | Q41: 2565.52 | R41: =P41/O41 -> 0.06169515
A43: TOTAL | B43: 590870.05 | C43: =sum(C12:C42) -> 4015 | D43: =B43/C43 -> 147.16564 | E43: 427478.16 | F43: =sum(F12:F42) -> 1178 | G43: =E43/F43 -> 362.88469 | H43: =B43-E43 -> 163391.89 | I43: =sum(I12:I42) -> 4768 | J43: =sum(J12:J42) -> 1148 | K43: =sum(K12:K42) -> 3190 | L43: =SUM(L12:L42) -> 0 | M43: =SUM(M12:M42)*6 -> 5469785.5 | N43: =SUM(N12:N42)*6 -> 6243.96 | O43: =SUM(O12:O42)*6 -> 5568174.4 | P43: =SUM(P12:P42)*6 -> 98809.74 | Q43: =SUM(Q12:Q42)*6 -> 98809.74 | R43: =P43/O43 -> 0.017745446
B44: DEPOSITOS | C44: QTD. DEP | D44: TICKET DEPOSITOS | E44: SAQUES | F44: QTD. SAQUE | G44: TICKET SAQUE | H44: NETCASH LIQUIDO | I44: CONVERSÃO FTD | K44: UAP | L44: REDEP. | M44: INATIVOS | N44: CHURN | O44: LTV | P44: TX. GETWAY | Q44: PLAT. FEE 15% | R44: MEDIA %
H45: =H43-P45 -> 144246.94 | I45: =J43/I43 -> 0.24077181 | M45: =I43-J43 -> 3620 | N45: =M45/I43 -> 0.75922819 | O45: =P43/J43 -> 86.071202 | P45: =(B43+E43)*0.0188 -> 19144.946 | Q45: =P43*0.18 -> 17785.753

Sheet DEZEMBRO
A9: TERMÔMETRO
B10: DEPOSITOS | E10: SAQUES | H10: BALANÇO | I10: GERAL | R10: Sportsbook | AA10: Cassino
A11: DATA | B11: Total | C11: QTD | D11: Ticket | E11: Total | F11: QTD | G11: Ticket | H11: Netcash Real | I11: REGISTROS | J11: FTD | K11: UAP | L11: UAP BASE | M11: TURNOVER | N11: GGR | O11: NGR | P11: GGR% | R11: UAP | S11: Número de Bets | T11: TURNOVER | U11: Média de Aposta por Usuário | V11: Ticket | W11: GGR | X11: NGR | Y11: GGR% | AA11: UAP | AB11: Número de Giros | AC11: TURNOVER | AD11: Vezes de start nos jogos por usuário | AE11: Ticket | AF11: GGR | AG11: NGR | AH11: GGR% | AK11: TICKET MÉDIO | AL11: NOVOS CLIENTES | AM11: CLIENTES INATIVOS | AN11: FTD (Priméiro depósito) | AO11: UAP (Clientes Recorrentes) | AP11: CHURN (taxa de Inativos) | AQ11: ARPUR (Receita média por usuário) | AR11: CAC. (Custo Aquisição) | AS11: Total Ações | AT11: Total Investido
A12: 45261 | B12: =33387.63*5.37 -> 179291.57 | C12: 3585 | D12: =B12/C12 -> 50.011596 | E12: =27143.35*5.37 -> 145759.79 | F12: 575 | G12: =E12/F12 -> 253.49529 | H12: =B12-E12 -> 33531.784 | I12: 1063 | J12: 740 | K12: 2306 | L12: =K12-J12 -> 1566 | M12: =216660*5.37 -> 1163464.2 | N12: =194.57*5.37 -> 1044.8409 | O12: =N12 -> 1044.8409 | P12: =O12/M12 -> 0.00089804302 | R12: 64 | S12: 297 | T12: =3491.31*5.37 -> 18748.335 | U12: =S12/R12 -> 4.640625 | V12: =T12/S12 -> 63.125706 | W12: =104.24*5.37 -> 559.7688 | X12: =W12 -> 559.7688 | Y12: =X12/T12 -> 0.029856988 | AA12: 2277 | AB12: 630663 | AC12: =213168.93*5.37 -> 1144717.2 | AD12: =AB12/AA12 -> 276.97101 | AE12: =AC12/AB12 -> 1.8151012 | AF12: =90.33*5.37 -> 485.0721 | AG12: =AF12 -> 485.0721 | AH12: =AF12/AC12 -> 0.00042374843 | AK12: =D43 -> 51.939878 | AL12: =I43 -> 25804 | AM12: =AL12-AN12 -> 9111 | AN12: =J43 -> 16693 | AO12: =K43 -> 1823.2903 | AP12: =AM12/AL12 -> 0.35308479 | AQ12: =N43/K43 -> 458.285 | AR12: =AS12/AN12 -> #REF! | AS12: ='CUSTOS 2023'!AS5 -> #REF! | AT12: ='CUSTOS 2023'!AS3 -> #REF!
A13: 45262 | B13: 155298.5 | C13: 3423 | D13: =B13/C13 -> 45.369121 | E13: 176433.24 | F13: 630 | G13: =E13/F13 -> 280.05276 | H13: =B13-E13 -> -21134.74 | I13: 949 | J13: =712-31 -> 681 | K13: 2295 | L13: =K13-J13 -> 1614 | M13: 2573500.6 | N13: -277420.18 | O13: =N13 -> -277420.18 | P13: =O13/M13 -> -0.10779876 | R13: 103 | S13: 391 | T13: 23109.05 | U13: =S13/R13 -> 3.7961165 | V13: =T13/S13 -> 59.10243 | W13: -2222.96 | X13: =W13 -> -2222.96 | Y13: =X13/T13 -> -0.096194348 | AA13: 2235 | AB13: 661167 | AC13: 2550391.6 | AD13: =AB13/AA13 -> 295.82416 | AE13: =AC13/AB13 -> 3.8574091 | AF13: -275197.22 | AG13: =AF13 -> -275197.22 | AH13: =AF13/AC13 -> -0.10790391
A14: 45263 | B14: 119493.82 | C14: 2655 | D14: =B14/C14 -> 45.007089 | E14: 133247.37 | F14: 468 | G14: =E14/F14 -> 284.7166 | H14: =B14-E14 -> -13753.55 | I14: 588 | J14: 434 | K14: 1801 | L14: =K14-J14 -> 1367 | M14: 2917958.2 | N14: 74918.37 | O14: =N14 -> 74918.37 | P14: =O14/M14 -> 0.025674929 | R14: 122 | S14: 506 | T14: 18822.86 | U14: =S14/R14 -> 4.147541 | V14: =T14/S14 -> 37.199328 | W14: 1196.46 | X14: =W14 -> 1196.46 | Y14: =X14/T14 -> 0.063564198 | AA14: 1735 | AB14: 535573 | AC14: 2899135.3 | AD14: =AB14/AA14 -> 308.68761 | AE14: =AC14/AB14 -> 5.4131469 | AF14: 73721.91 | AG14: =AF14 -> 73721.91 | AH14: =AF14/AC14 -> 0.02542893 | AK14: NETCASH | AL14: RETENÇÃO STARS
A15: 45264 | B15: 125915.53 | C15: 2416 | D15: =B15/C15 -> 52.117355 | E15: 111151.31 | F15: 449 | G15: =E15/F15 -> 247.55303 | H15: =B15-E15 -> 14764.22 | I15: 577 | J15: 395 | K15: 1634 | L15: =K15-J15 -> 1239 | M15: 1085732.2 | N15: 20537.86 | O15: =N15 -> 20537.86 | P15: =O15/M15 -> 0.018916138 | R15: 54 | S15: 261 | T15: 11140.33 | U15: =S15/R15 -> 4.8333333 | V15: =T15/S15 -> 42.683257 | W15: -747 | X15: =W15 -> -747 | Y15: =X15/T15 -> -0.067053669 | AA15: 1602 | AB15: 469900 | AC15: 1074591.9 | AD15: =AB15/AA15 -> 293.32085 | AE15: =AC15/AB15 -> 2.2868522 | AF15: 21285.2 | AG15: =AF15 -> 21285.2 | AH15: =AF15/AC15 -> 0.019807707 | AK15: =B43-E43 -> 689268.06 | AL15: =(B43+E43)*0.0143 -> 120267.1
A16: 45265 | B16: 131848.64 | C16: 2746 | D16: =B16/C16 -> 48.0148 | E16: 134904.2 | F16: 498 | G16: =E16/F16 -> 270.89197 | H16: =B16-E16 -> -3055.56 | I16: 530 | J16: 355 | K16: 1692 | L16: =K16-J16 -> 1337 | M16: 858783.97 | N16: 67758.21 | O16: =N16 -> 67758.21 | P16: =O16/M16 -> 0.07890018 | R16: 65 | S16: 286 | T16: 15156.7 | U16: =S16/R16 -> 4.4 | V16: =T16/S16 -> 52.995455 | W16: 1175.58 | X16: =W16 -> 1175.58 | Y16: =X16/T16 -> 0.077561738 | AA16: 1654 | AB16: 489487 | AC16: 843627.26 | AD16: =AB16/AA16 -> 295.94135 | AE16: =AC16/AB16 -> 1.7234927 | AF16: 66582.26 | AG16: =AF16 -> 66582.26 | AH16: =AF16/AC16 -> 0.078923789
A17: 45266 | B17: 128534.64 | C17: 3009 | D17: =B17/C17 -> 42.71673 | E17: 88810.38 | F17: 503 | G17: =E17/F17 -> 176.56139 | H17: =B17-E17 -> 39724.26 | I17: 703 | J17: 436 | K17: 1868 | L17: =K17-J17 -> 1432 | M17: 967983.01 | N17: 34681.67 | O17: =N17 -> 34681.67 | P17: =O17/M17 -> 0.0358288 | R17: 190 | S17: 716 | T17: 26360.33 | U17: =S17/R17 -> 3.7684211 | V17: =T17/S17 -> 36.816103 | W17: 4495.92 | X17: =W17 -> 4495.92 | Y17: =X17/T17 -> 0.17055629 | AA17: 1749 | AB17: 491192 | AC17: 941622.68 | AD17: =AB17/AA17 -> 280.84162 | AE17: =AC17/AB17 -> 1.9170155 | AF17: 30185.75 | AG17: =AF17 -> 30185.75 | AH17: =AF17/AC17 -> 0.032057161
A18: 45267 | B18: 145783.42 | C18: 2995 | D18: =B18/C18 -> 48.675599 | E18: 97841.25 | F18: 520 | G18: =E18/F18 -> 188.15625 | H18: =B18-E18 -> 47942.17 | I18: 814 | J18: 499 | K18: 1933 | L18: =K18-J18 -> 1434 | M18: 860362.14 | N18: 32495.19 | O18: =N18 -> 32495.19 | P18: =O18/M18 -> 0.0377692 | R18: 114 | S18: 373 | T18: 7996.63 | U18: =S18/R18 -> 3.2719298 | V18: =T18/S18 -> 21.438686 | W18: 696.82 | X18: =W18 -> 696.82 | Y18: =X18/T18 -> 0.087139207 | AA18: 1871 | AB18: 513660 | AC18: 852365.91 | AD18: =AB18/AA18 -> 274.53768 | AE18: =AC18/AB18 -> 1.6593971 | AF18: 31798.37 | AG18: =AF18 -> 31798.37 | AH18: =AF18/AC18 -> 0.037306009
A19: 45268 | B19: 146450.32 | C19: 2763 | D19: =B19/C19 -> 53.004097 | E19: 183876.71 | F19: 495 | G19: =E19/F19 -> 371.4681 | H19: =B19-E19 -> -37426.39 | I19: 650 | J19: 400 | K19: 1732 | L19: =K19-J19 -> 1332 | M19: 1171742.2 | N19: 14661.7 | O19: =N19 -> 14661.7 | P19: =O19/M19 -> 0.012512735 | R19: 60 | S19: 282 | T19: 11241.54 | U19: =S19/R19 -> 4.7 | V19: =T19/S19 -> 39.863617 | W19: 84.91 | X19: =W19 -> 84.91 | Y19: =X19/T19 -> 0.0075532356 | AA19: 1696 | AB19: 504169 | AC19: 1160500.7 | AD19: =AB19/AA19 -> 297.26946 | AE19: =AC19/AB19 -> 2.3018089 | AF19: 14576.79 | AG19: =AF19 -> 14576.79 | AH19: =AF19/AC19 -> 0.012560777
A20: 45269 | B20: 187564.39 | C20: 3146 | D20: =B20/C20 -> 59.619959 | E20: 141817.91 | F20: 483 | G20: =E20/F20 -> 293.61886 | H20: =B20-E20 -> 45746.48 | I20: 729 | J20: 559 | K20: 1904 | L20: =K20-J20 -> 1345 | M20: 1210098.1 | N20: 36626.36 | O20: =N20 -> 36626.36 | P20: =O20/M20 -> 0.030267264 | R20: 78 | S20: 333 | T20: 10407.8 | U20: =S20/R20 -> 4.2692308 | V20: =T20/S20 -> 31.254655 | W20: 543.28 | X20: =W20 -> 543.28 | Y20: =X20/T20 -> 0.052199312 | AA20: 1863 | AB20: 539434 | AC20: 1199690.3 | AD20: =AB20/AA20 -> 289.55126 | AE20: =AC20/AB20 -> 2.2239798 | AF20: 36083.08 | AG20: =AF20 -> 36083.08 | AH20: =AF20/AC20 -> 0.030076995
A21: 45270 | B21: 106983.99 | C21: 2293 | D21: =B21/C21 -> 46.656777 | E21: 93920.49 | F21: 403 | G21: =E21/F21 -> 233.05333 | H21: =B21-E21 -> 13063.5 | I21: 456 | J21: 302 | K21: 1432 | L21: =K21-J21 -> 1130 | M21: 888147.45 | N21: 33638.67 | O21: =N21 -> 33638.67 | P21: =O21/M21 -> 0.037875096 | R21: 54 | S21: 255 | T21: 17218.62 | U21: =S21/R21 -> 4.7222222 | V21: =T21/S21 -> 67.524 | W21: -576.89 | X21: =W21 -> -576.89 | Y21: =X21/T21 -> -0.033503846 | AA21: 1400 | AB21: 433888 | AC21: 870928.83 | AD21: =AB21/AA21 -> 309.92 | AE21: =AC21/AB21 -> 2.0072665 | AF21: 34215.56 | AG21: =AF21 -> 34215.56 | AH21: =AF21/AC21 -> 0.039286287
A22: 45271 | B22: 135274.02 | C22: 2339 | D22: =B22/C22 -> 57.834126 | E22: 103078.61 | F22: 375 | G22: =E22/F22 -> 274.87629 | H22: =B22-E22 -> 32195.41 | I22: 379 | J22: 252 | K22: 1376 | L22: =K22-J22 -> 1124 | M22: 885881.54 | N22: 57195.45 | O22: =N22 -> 57195.45 | P22: =O22/M22 -> 0.064563316 | R22: 43 | S22: 139 | T22: 6014.93 | U22: =S22/R22 -> 3.2325581 | V22: =T22/S22 -> 43.272878 | W22: 160.91 | X22: =W22 -> 160.91 | Y22: =X22/T22 -> 0.026751766 | AA22: 1349 | AB22: 398849 | AC22: 879866.61 | AD22: =AB22/AA22 -> 295.66271 | AE22: =AC22/AB22 -> 2.2060143 | AF22: 57034.54 | AG22: =AF22 -> 57034.54 | AH22: =AF22/AC22 -> 0.064821803
A23: 45272 | B23: 154376.91 | C23: 2611 | D23: =B23/C23 -> 59.125588 | E23: 129232.44 | F23: 477 | G23: =E23/F23 -> 270.92755 | H23: =B23-E23 -> 25144.47 | I23: 573 | J23: 369 | K23: 1605 | L23: =K23-J23 -> 1236 | M23: 888844.04 | N23: 15352.99 | O23: =N23 -> 15352.99 | P23: =O23/M23 -> 0.017272985 | R23: 94 | S23: 354 | T23: 57650.66 | U23: =S23/R23 -> 3.7659574 | V23: =T23/S23 -> 162.85497 | W23: 12243.06 | X23: =W23 -> 12243.06 | Y23: =X23/T23 -> 0.21236635 | AA23: 1557 | AB23: 433236 | AC23: 831193.33 | AD23: =AB23/AA23 -> 278.25048 | AE23: =AC23/AB23 -> 1.9185694 | AF23: 3109.93 | AG23: =AF23 -> 3109.93 | AH23: =AF23/AC23 -> 0.0037415242
A24: 45273 | B24: 131886.74 | C24: 2508 | D24: =B24/C24 -> 52.586419 | E24: 101120.51 | F24: 447 | G24: =E24/F24 -> 226.22038 | H24: =B24-E24 -> 30766.23 | I24: 655 | J24: 439 | K24: 1638 | L24: =K24-J24 -> 1199 | M24: 1189264.9 | N24: 42484.56 | O24: =N24 -> 42484.56 | P24: =O24/M24 -> 0.035723378 | R24: 91 | S24: 375 | T24: 58008.02 | U24: =S24/R24 -> 4.1208791 | V24: =T24/S24 -> 154.68805 | W24: 5175.31 | X24: =W24 -> 5175.31 | Y24: =X24/T24 -> 0.089217146 | AA24: 1583 | AB24: 444606 | AC24: 1131256.9 | AD24: =AB24/AA24 -> 280.86292 | AE24: =AC24/AB24 -> 2.5444031 | AF24: 37309.25 | AG24: =AF24 -> 37309.25 | AH24: =AF24/AC24 -> 0.032980351
A25: 45274 | B25: 133448.64 | C25: 2506 | D25: =B25/C25 -> 53.251652 | E25: 106357.82 | F25: 445 | G25: =E25/F25 -> 239.00634 | H25: =B25-E25 -> 27090.82 | I25: 622 | J25: 394 | K25: 1579 | L25: =K25-J25 -> 1185 | M25: 993111.09 | N25: 30506.36 | O25: =N25 -> 30506.36 | P25: =O25/M25 -> 0.030717973 | R25: 59 | S25: 315 | T25: 73235.88 | U25: =S25/R25 -> 5.3389831 | V25: =T25/S25 -> 232.49486 | W25: 2400.16 | X25: =W25 -> 2400.16 | Y25: =X25/T25 -> 0.032773007 | AA25: 1541 | AB25: 474608 | AC25: 919875.21 | AD25: =AB25/AA25 -> 307.98702 | AE25: =AC25/AB25 -> 1.9381789 | AF25: 28106.2 | AG25: =AF25 -> 28106.2 | AH25: =AF25/AC25 -> 0.030554362
A26: 45275 | B26: 135367.2 | C26: 2504 | D26: =B26/C26 -> 54.060383 | E26: 104060.7 | F26: 436 | G26: =E26/F26 -> 238.67133 | H26: =B26-E26 -> 31306.5 | I26: 587 | J26: 408 | K26: 1540 | L26: =K26-J26 -> 1132 | M26: 940311.27 | N26: 51918.64 | O26: =N26 -> 51918.64 | P26: =O26/M26 -> 0.055214312 | R26: 54 | S26: 266 | T26: 83169.94 | U26: =S26/R26 -> 4.9259259 | V26: =T26/S26 -> 312.66895 | W26: 16257.81 | X26: =W26 -> 16257.81 | Y26: =X26/T26 -> 0.195477 | AA26: 1514 | AB26: 438572 | AC26: 857141.33 | AD26: =AB26/AA26 -> 289.67768 | AE26: =AC26/AB26 -> 1.9543914 | AF26: 35660.83 | AG26: =AF26 -> 35660.83 | AH26: =AF26/AC26 -> 0.041604376
A27: 45276 | B27: 123656.44 | C27: 2301 | D27: =B27/C27 -> 53.740304 | E27: 86153.1 | F27: 401 | G27: =E27/F27 -> 214.84564 | H27: =B27-E27 -> 37503.34 | I27: 379 | J27: 203 | K27: 1486 | L27: =K27-J27 -> 1283 | M27: 1005762.1 | N27: 33580.81 | O27: =N27 -> 33580.81 | P27: =O27/M27 -> 0.033388422 | R27: 66 | S27: 305 | T27: 68651.87 | U27: =S27/R27 -> 4.6212121 | V27: =T27/S27 -> 225.0881 | W27: -1804.68 | X27: =W27 -> -1804.68 | Y27: =X27/T27 -> -0.026287412 | AA27: 1445 | AB27: 445255 | AC27: 937110.25 | AD27: =AB27/AA27 -> 308.13495 | AE27: =AC27/AB27 -> 2.1046597 | AF27: 35385.49 | AG27: =AF27 -> 35385.49 | AH27: =AF27/AC27 -> 0.037760221
... A42: 45291 | B42: 149860.84 | C42: 2867 | D42: =B42/C42 -> 52.270959 | E42: 123328 | F42: 507 | G42: =E42/F42 -> 243.25049 | H42: =B42-E42 -> 26532.84 | I42: 1184 | J42: 724 | K42: 2092 | L42: =K42-J42 -> 1368 | M42: 1155114.9 | N42: 26681.48 | O42: =N42 -> 26681.48 | P42: =O42/M42 -> 0.023098551 | R42: 83 | S42: 287 | T42: 100912.81 | U42: =S42/R42 -> 3.4578313 | V42: =T42/S42 -> 351.61258 | W42: -390.18 | X42: =W42 -> -390.18 | Y42: =X42/T42 -> -0.0038665061 | AA42: 2049 | AB42: 586551 | AC42: 1054202.1 | AD42: =AB42/AA42 -> 286.26208 | AE42: =AC42/AB42 -> 1.7972897 | AF42: 27071.66 | AG42: =AF42 -> 27071.66 | AH42: =AF42/AC42 -> 0.025679763
A43: TOTAL | B43: =SUM(B12:B42) -> 4549777.5 | C43: =SUM(C11:C42) -> 87597 | D43: =B43/C43 -> 51.939878 | E43: =SUM(E12:E42) -> 3860509.4 | F43: =SUM(F12:F42) -> 15296 | G43: =E43/F43 -> 252.38686 | H43: =B43-E43 -> 689268.06 | I43: =SUM(I12:I42) -> 25804 | J43: =SUM(J12:J42) -> 16693 | K43: =AVERAGE(K12:K42) -> 1823.2903 | L43: =AVERAGE(L12:L42) -> 1284.8065 | M43: =SUM(M12:M41) -> 34484861 | N43: =SUM(N12:N42) -> 835586.6 | O43: =AVERAGE(O12:O42) -> 26954.406 | P43: =N43/M43 -> 0.024230534 | R43: =SUM(R11:R42) -> 2544 | S43: =SUM(S11:S42) -> 10388 | T43: =SUM(T12:T42) -> 1567045.5 | U43: =S43/R43 -> 4.0833333 | V43: =T43/S43 -> 150.85151 | W43: =SUM(W12:W42) -> 91661.589 | X43: =SUM(X12:X41) -> 92051.769 | Y43: =W43/T43 -> 0.058493254 | AA43: =SUM(AA12:AA42) -> 55125 | AB43: =SUM(AB12:AB42) -> 15453562 | AC43: =SUM(AC12:AC42) -> 34072932 | AD43: =AVERAGE(AD12:AD40) -> 281.70743 | AE43: =AC43/AB43 -> 2.2048594 | AF43: =SUM(AF12:AF42) -> 743924.92 | AG43: =SUM(AG12:AG41) -> 716853.26 | AH43: =AG43/AC43 -> 0.02103879
A44: NETCASH BRUTO | B44: DEPOSITOS | C44: QTD. DEP | D44: TICKET DEP. | E44: SAQUES | F44: QTD. SAQ | G44: TICKET SAQ. | H44: NETCASH REAL | I44: CONVERSÃO FTD | K44: MEDIA UAP | L44: BASE UAP | M44: TURNOVER | N44: GGR TOTAL | O44: MEDIA GGR | P44: MEDIA % | R44: LTV Sportingbook | S44: =V43*U43*1 -> 615.977 | AA44: LTV Cassino | AB44: =AB45*AD43*1 -> 621.12529
A45: =B43-E43+'CUSTOS 2023'!AS94+'CUSTOS 2023'!AS66-'CUSTOS 2023'!AS80 -> #REF! | I45: =J43/I43 -> 0.64691521 | R45: TICKET MÉDIO Sportingbook | S45: =V43 -> 150.85151 | AA45: TICKET MÉDIO Cassino | AB45: =AE43 -> 2.2048594

Sheet NOVEMBRO
A9: TERMÔMETRO
B10: DEPOSITOS | E10: SAQUES | I10: GERAL | R10: Sportsbook | AA10: Cassino
A11: DATA | B11: Total | C11: QTD | D11: Ticket | E11: Total | F11: QTD | G11: Ticket | H11: Netcash Real | I11: REGISTROS | J11: FTD | K11: UAP | L11: UAP BASE | M11: TURNOVER | N11: GGR | O11: NGR | P11: GGR% | R11: UAP | S11: Número de Bets | T11: TURNOVER | U11: Média de Aposta por Usuário | V11: Ticket | W11: GGR | X11: NGR | Y11: GGR% | AA11: UAP | AB11: Número de Giros | AC11: TURNOVER | AD11: Vezes de start nos jogos por usuário | AE11: Ticket | AF11: GGR | AG11: NGR | AH11: GGR% | AK11: TICKET MÉDIO | AL11: NOVOS CLIENTES | AM11: CLIENTES INATIVOS | AN11: FTD (Priméiro depósito) | AO11: UAP (Clientes Recorrentes) | AP11: CHURN (taxa de Inativos) | AQ11: ARPUR (Receita média por usuário) | AR11: CAC. (Custo Aquisição) | AS11: Total Ações | AT11: Total Investido
A12: 45231 | B12: 124242.92 | C12: 2255 | D12: =B12/C12 -> 55.096639 | E12: 80719.97 | F12: 405 | G12: =E12/F12 -> 199.30857 | H12: =B12-E12 -> 43522.95 | I12: 749 | J12: 510 | K12: 1501 | L12: =K12-J12 -> 991 | M12: 679550.71 | N12: =W12+AF12 -> 33894.06 | O12: =N12 -> 33894.06 | P12: =O12/M12 -> 0.049877161 | R12: 114 | S12: 397 | T12: 25236.27 | U12: =S12/R12 -> 3.4824561 | V12: =T12/S12 -> 63.567431 | W12: -4311.72 | X12: =W12 -> -4311.72 | Y12: =X12/T12 -> -0.17085409 | AA12: 1428 | AB12: 396731 | AC12: 654314.26 | AD12: =AB12/AA12 -> 277.82283 | AE12: =AC12/AB12 -> 1.6492643 | AF12: 38205.78 | AG12: =AF12 -> 38205.78 | AH12: =AF12/AC12 -> 0.058390566 | AK12: =D42 -> 52.770186 | AL12: =I42 -> 21408 | AM12: =AL12-AN12 -> 6562 | AN12: =J42 -> 14846 | AO12: =K42 -> 1666.4333 | AP12: =AM12/AL12 -> 0.30652093 | AQ12: =N42/K42 -> 536.44 | AR12: =AS12/AN12 -> #REF! | AS12: ='CUSTOS 2023'!AN5 -> #REF! | AT12: ='CUSTOS 2023'!AN3 -> #REF!
A13: 45232 | B13: 101923.32 | C13: 2019 | D13: =B13/C13 -> 50.48208 | E13: 79407.03 | F13: 366 | G13: =E13/F13 -> 216.9591 | H13: =B13-E13 -> 22516.29 | I13: 477 | J13: 351 | K13: 1346 | L13: =K13-J13 -> 995 | M13: 772747.23 | N13: =W13+AF13 -> 19474.84 | O13: =N13 -> 19474.84 | P13: =O13/M13 -> 0.025202083 | R13: 78 | S13: 257 | T13: 35215.68 | U13: =S13/R13 -> 3.2948718 | V13: =T13/S13 -> 137.02599 | W13: -3126.48 | X13: -3791.25 | Y13: =X13/T13 -> -0.10765801 | AA13: 1298 | AB13: 371122 | AC13: 737531.55 | AD13: =AB13/AA13 -> 285.91834 | AE13: =AC13/AB13 -> 1.9873022 | AF13: 22601.32 | AG13: 22601.32 | AH13: =AF13/AC13 -> 0.030644547
A14: 45233 | B14: 80070.16 | C14: 1961 | D14: =B14/C14 -> 40.83129 | E14: 70772.88 | F14: 339 | G14: =E14/F14 -> 208.76956 | H14: =B14-E14 -> 9297.28 | I14: 803 | J14: 441 | K14: 1311 | L14: =K14-J14 -> 870 | M14: 850446.23 | N14: =W14+AF14 -> 17587.48 | O14: =N14 -> 17587.48 | P14: =O14/M14 -> 0.020680296 | R14: 70 | S14: 265 | T14: 24355.6 | U14: =S14/R14 -> 3.7857143 | V14: =T14/S14 -> 91.907925 | W14: 11721.65 | X14: 8439.9 | Y14: =X14/T14 -> 0.34652811 | AA14: 1274 | AB14: 353891 | AC14: 826090.63 | AD14: =AB14/AA14 -> 277.77943 | AE14: =AC14/AB14 -> 2.3343081 | AF14: 5865.83 | AG14: 5865.83 | AH14: =AF14/AC14 -> 0.00710071 | AK14: NETCASH | AL14: RETENÇÃO STARS | AM14: RETIRADAS MÊS
A15: 45234 | B15: 99700 | C15: 2322 | D15: =B15/C15 -> 42.937123 | E15: 67990 | F15: 363 | G15: =E15/F15 -> 187.30028 | H15: =B15-E15 -> 31710 | I15: 481 | J15: 476 | K15: 1456 | L15: =K15-J15 -> 980 | M15: 579669.59 | N15: =W15+AF15 -> 29183.23 | O15: =N15 -> 29183.23 | P15: =O15/M15 -> 0.050344594 | R15: 118 | S15: 455 | T15: 12488.36 | U15: =S15/R15 -> 3.8559322 | V15: =T15/S15 -> 27.446945 | W15: 5211.78 | X15: =W15 -> 5211.78 | Y15: =X15/T15 -> 0.41733102 | AA15: 1378 | AB15: 381650 | AC15: 567181.23 | AD15: =AB15/AA15 -> 276.95936 | AE15: =AC15/AB15 -> 1.4861293 | AF15: 23971.45 | AG15: =AF15 -> 23971.45 | AH15: =AF15/AC15 -> 0.042264181 | AK15: =B42-E42 -> 831255.1 | AL15: =(B42+E42)*0.0143 -> 101004.76 | AM15: =120.84+384.9+150571+75600+100572+109933+101174+60000+100813 -> 699168.74
A16: 45235 | B16: 91946.74 | C16: 1747 | D16: =B16/C16 -> 52.631219 | E16: 61238.83 | F16: 280 | G16: =E16/F16 -> 218.71011 | H16: =B16-E16 -> 30707.91 | I16: 509 | J16: 326 | K16: 1218 | L16: =K16-J16 -> 892 | M16: 580278.48 | N16: -9994.78 | O16: =N16 -> -9994.78 | P16: =O16/M16 -> -0.017224109 | R16: 105 | S16: 386 | T16: 5696.3 | U16: =S16/R16 -> 3.6761905 | V16: =T16/S16 -> 14.757254 | W16: 568 | X16: 562.82 | Y16: =X16/T16 -> 0.098804487 | AA16: 1154 | AB16: 344529 | AC16: 574582.18 | AD16: =AB16/AA16 -> 298.55199 | AE16: =AC16/AB16 -> 1.6677324 | AF16: -10563.52 | AG16: -10655.53 | AH16: =AF16/AC16 -> -0.018384698
A17: 45236 | B17: 127103.41 | C17: 2085 | D17: =B17/C17 -> 60.960868 | E17: 93494.9 | F17: 387 | G17: =E17/F17 -> 241.58889 | H17: =B17-E17 -> 33608.51 | I17: 643 | J17: 413 | K17: 1419 | L17: =K17-J17 -> 1006 | M17: 738229.46 | N17: 49909.16 | O17: =N17 -> 49909.16 | P17: =O17/M17 -> 0.067606568 | R17: 79 | S17: 186 | T17: 6882.18 | U17: =S17/R17 -> 2.3544304 | V17: =T17/S17 -> 37.000968 | W17: 2963.02 | X17: =W17 -> 2963.02 | Y17: =X17/T17 -> 0.43053509 | AA17: 1379 | AB17: 407876 | AC17: 731346.94 | AD17: =AB17/AA17 -> 295.77665 | AE17: =AC17/AB17 -> 1.793062 | AF17: 46946.14 | AG17: =AF17 -> 46946.14 | AH17: =AF17/AC17 -> 0.06419134
A18: 45237 | B18: 189036.76 | C18: 2504 | D18: =B18/C18 -> 75.493914 | E18: 127352.97 | F18: 441 | G18: =E18/F18 -> 288.78224 | H18: =B18-E18 -> 61683.79 | I18: 616 | J18: 424 | K18: 1607 | L18: =K18-J18 -> 1183 | M18: 1137346.1 | N18: 14587.56 | O18: =N18 -> 14587.56 | P18: =O18/M18 -> 0.012825964 | R18: 96 | S18: 286 | T18: 5468.06 | U18: =S18/R18 -> 2.9791667 | V18: =T18/S18 -> 19.119091 | W18: -1309.38 | X18: -1387.68 | Y18: =X18/T18 -> -0.25377922 | AA18: 1554 | AB18: 433994 | AC18: 1131878 | AD18: =AB18/AA18 -> 279.27542 | AE18: =AC18/AB18 -> 2.60805 | AF18: 15896.94 | AG18: 15855.35 | AH18: =AF18/AC18 -> 0.014044746
A19: 45238 | B19: 147042.65 | C19: 2611 | D19: =B19/C19 -> 56.316603 | E19: 143417.43 | F19: 478 | G19: =E19/F19 -> 300.03646 | H19: =B19-E19 -> 3625.22 | I19: 699 | J19: 473 | K19: 1804 | L19: =K19-J19 -> 1331 | M19: 1592581.3 | N19: -35061.04 | O19: =N19 -> -35061.04 | P19: =O19/M19 -> -0.022015228 | R19: 152 | S19: 476 | T19: 50319.12 | U19: =S19/R19 -> 3.1315789 | V19: =T19/S19 -> 105.71244 | W19: 820.47 | X19: =W19 -> 820.47 | Y19: =X19/T19 -> 0.016305333 | AA19: 1719 | AB19: 410063 | AC19: 1542262.1 | AD19: =AB19/AA19 -> 238.54741 | AE19: =AC19/AB19 -> 3.7610371 | AF19: -35881.51 | AG19: =AF19 -> -35881.51 | AH19: =AF19/AC19 -> -0.023265507
A20: 45239 | B20: 141465.27 | C20: 2417 | D20: =B20/C20 -> 58.52928 | E20: 108360.66 | F20: 411 | G20: =E20/F20 -> 263.65124 | H20: =B20-E20 -> 33104.61 | I20: 767 | J20: 428 | K20: 1638 | L20: =K20-J20 -> 1210 | M20: 1312010.7 | N20: 148974.56 | O20: =N20 -> 148974.56 | P20: =O20/M20 -> 0.11354676 | R20: 150 | S20: 464 | T20: 33465.28 | U20: =S20/R20 -> 3.0933333 | V20: =T20/S20 -> 72.123448 | W20: 15255.44 | X20: =W20 -> 15255.44 | Y20: =X20/T20 -> 0.45585873 | AA20: 1558 | AB20: 414505 | AC20: 1278545.4 | AD20: =AB20/AA20 -> 266.04942 | AE20: =AC20/AB20 -> 3.0845115 | AF20: 133719.12 | AG20: =AF20 -> 133719.12 | AH20: =AF20/AC20 -> 0.10458691
A21: 45240 | B21: 160623.86 | C21: 2787 | D21: =B21/C21 -> 57.633247 | E21: 97541.12 | F21: 466 | G21: =E21/F21 -> 209.31571 | H21: =B21-E21 -> 63082.74 | I21: 1063 | J21: 677 | K21: 1871 | L21: =K21-J21 -> 1194 | M21: 918204.65 | N21: 40573.04 | O21: =N21 -> 40573.04 | P21: =O21/M21 -> 0.044187361 | R21: 79 | S21: 256 | T21: 8752.87 | U21: =S21/R21 -> 3.2405063 | V21: =T21/S21 -> 34.190898 | W21: 435.53 | X21: =W21 -> 435.53 | Y21: =X21/T21 -> 0.049758536 | AA21: 1823 | AB21: 445127 | AC21: 909451.78 | AD21: =AB21/AA21 -> 244.17279 | AE21: =AC21/AB21 -> 2.0431288 | AF21: 40137.51 | AG21: =AF21 -> 40137.51 | AH21: =AF21/AC21 -> 0.044133742
A22: 45241 | B22: 126226.53 | C22: 2574 | D22: =B22/C22 -> 49.039056 | E22: 100944.8 | F22: 520 | G22: =E22/F22 -> 194.12462 | H22: =B22-E22 -> 25281.73 | I22: 671 | J22: 532 | K22: 1808 | L22: =K22-J22 -> 1276 | M22: 878672.97 | N22: 38827.5 | O22: =N22 -> 38827.5 | P22: =O22/M22 -> 0.044188795 | R22: 111 | S22: 473 | T22: 15153.96 | U22: =S22/R22 -> 4.2612613 | V22: =T22/S22 -> 32.03797 | W22: -386.95 | X22: =W22 -> -386.95 | Y22: =X22/T22 -> -0.02553458 | AA22: 1747 | AB22: 430542 | AC22: 863519.01 | AD22: =AB22/AA22 -> 246.44648 | AE22: =AC22/AB22 -> 2.0056557 | AF22: 39214.45 | AG22: =AF22 -> 39214.45 | AH22: =AF22/AC22 -> 0.045412376
